Workbook

Sheet Leeme
A1: CubeSat UD34 – Práctica 3: matrices, comparaciones y presupuestos
A2: Luis Alberto Ardila Páez · Daniel Esteban Tirado Rojas · Universidad de Antioquia · 2026-2
A4: Convenciones
A5: 3,45 | B5: Entrada editable (azul, fondo amarillo): supuestos y datos de componentes. Si cambian un componente, editen solo estas celdas.
A6: 54,2 | B6: Fórmula (negro): se recalcula sola. No escribir encima.
A7: 1294 | B7: Vínculo a otra hoja (verde).
A8: Total | B8: Resultado clave que se reporta en el informe.
A10: Hojas
A11: Orbita | B11: Órbita de referencia, distancias a la estación, pases y oportunidades de captura.
A12: Camara_Datos | B12: GSD, barrido, cuadros por escena, volumen de datos, almacenamiento y capacidad de bajada.
A13: Enlaces | B13: Presupuestos de enlace UHF bajada, banda S bajada y UHF subida.
A14: Potencia_Masa | B14: Generación solar, consumo diario, margen, batería, masa, centro de masa y altura de pila.
A15: Procesamiento | B15: Carga estimada de CPU y memoria.
A16: Matrices | B16: Pesos de criterios y matrices de decisión ponderadas D1–D8.
A17: Requisitos | B17: Matriz de requisitos (RF, RNF, RA, RN) con origen, prioridad y criterio de aceptación.
A18: Especificaciones | B18: Especificaciones técnicas ET-01 a ET-40 con requisitos asociados y fundamento.
A19: Trazabilidad | B19: Requisito → especificación → elemento de arquitectura → verificación.
A20: Interfaces | B20: Interfaces IF-01 a IF-18.
A21: TBD_Riesgos | B21: Valores por determinar con plan de cierre y registro de riesgos.
A22: Componentes | B22: Componentes candidatos por tarjeta con fabricante, referencia y enlace a la hoja de datos; la hoja Hallazgos_Componentes recoge lo que cambia al elegirlos.
A23: Nota | B23: Consumos y masas son estimaciones de orden de magnitud (rangos típicos de CubeSat, NASA State-of-the-Art of Small Spacecraft Technology). Se reemplazan por valores de hoja de datos en la Práctica 4; los presupuestos se actualizan solos.

Sheet Orbita
A1: Órbita de referencia y geometría de contacto
A2: Relaciones de Wertz & Larson, SMAD (3.ª ed.).
A4: Parámetro | B4: Valor | C4: Unidad | D4: Nota / fuente
A5: Radio terrestre R_E | B5: 6378 | C5: km | D5: Radio ecuatorial.
A6: Altitud h | B6: 550 | C6: km | D6: Enunciado.
A7: Parámetro gravitacional μ | B7: 398600.4 | C7: km³/s²
A8: Semieje mayor a | B8: =Orbita!$B$5+Orbita!$B$6 -> 6928 | C8: km | D8: a = R_E + h
A9: Periodo orbital T | B9: =2*PI()*SQRT(Orbita!$B$8^3/Orbita!$B$7) -> 5738.8229 | C9: s | D9: T = 2π√(a³/μ)
A10: Periodo orbital T | B10: =Orbita!$B$9/60 -> 95.647048 | C10: min
A11: Órbitas por día | B11: =86400/Orbita!$B$9 -> 15.055352 | C11: –
A12: Velocidad orbital v | B12: =SQRT(Orbita!$B$7/Orbita!$B$8) -> 7.5851631 | C12: km/s | D12: v = √(μ/a)
A13: Velocidad de la traza en tierra | B13: =Orbita!$B$12*Orbita!$B$5/Orbita!$B$8 -> 6.9829923 | C13: km/s | D13: Sin rotación terrestre.
A14: Radio angular de la Tierra ρ | B14: =DEGREES(ASIN(Orbita!$B$5/Orbita!$B$8)) -> 67.015718 | C14: ° | D14: sin ρ = R_E/a
A15: Eclipse máximo (β = 0) | B15: =Orbita!$B$10*2*Orbita!$B$14/360 -> 35.610309 | C15: min | D15: Peor caso.
A16: Fracción iluminada (peor caso) | B16: =1-Orbita!$B$15/Orbita!$B$10 -> 0.62769045 | C16: –
A17: Separación entre trazas en el ecuador | B17: =2*PI()*Orbita!$B$5/Orbita!$B$11 -> 2661.788 | C17: km | D17: Circunferencia / órbitas por día.
A19: Geometría de contacto con Medellín
A20: Parámetro | B20: UHF | C20: Banda S | D20: Nota / fuente
A21: Elevación mínima ε (°) | B21: 10 | C21: 20 | D21: S-03: en banda S se exige 20° por margen y por las laderas del valle de Aburrá.
A22: Ángulo nadir η (°) | B22: =DEGREES(ASIN(Orbita!$B$5/Orbita!$B$8*COS(RADIANS(Orbita!$B$21)))) -> 65.043155 | C22: =DEGREES(ASIN(Orbita!$B$5/Orbita!$B$8*COS(RADIANS(Orbita!$C$21)))) -> 59.893248 | D22: sin η = (R_E/a)·cos ε
A23: Ángulo central λ (°) | B23: =90-Orbita!$B$21-Orbita!$B$22 -> 14.956845 | C23: =90-Orbita!$C$21-Orbita!$C$22 -> 10.106752 | D23: λ = 90° − ε − η
A24: Distancia máxima D (km) | B24: =Orbita!$B$5*SIN(RADIANS(Orbita!$B$23))/SIN(RADIANS(Orbita!$B$22)) -> 1815.6412 | C24: =Orbita!$B$5*SIN(RADIANS(Orbita!$C$23))/SIN(RADIANS(Orbita!$C$22)) -> 1293.7683 | D24: D = R_E·sin λ / sin η. Alimenta la hoja Enlaces.
A25: Radio del círculo de visibilidad (km) | B25: =Orbita!$B$5*RADIANS(Orbita!$B$23) -> 1664.9526 | C25: =Orbita!$B$5*RADIANS(Orbita!$C$23) -> 1125.0544
A26: Pases por día (estimación geométrica) | B26: =2*2*Orbita!$B$25/Orbita!$B$17 -> 2.5020063 | C26: =2*2*Orbita!$C$25/Orbita!$B$17 -> 1.6906746 | D26: Trazas ascendentes + descendentes: ancho de acceso / separación.
A27: Duración máxima de pase (s) | B27: =Orbita!$B$9*2*Orbita!$B$23/360 -> 476.85936 | C27: =Orbita!$B$9*2*Orbita!$C$23/360 -> 322.22701 | D27: Pase cenital.
A28: Duración media de pase (s) | B28: =Orbita!$B$27*PI()/4 -> 374.52447 | C28: =Orbita!$C$27*PI()/4 -> 253.0765 | D28: Cuerda media = π/4 del diámetro.
A29: Pases por día usados en el diseño | B29: 2 | C29: 1.5 | D29: Conservador frente a la estimación geométrica (TBD-01).
A30: Duración útil usada (s) | B30: 300 | C30: 240 | D30: Conservador (TBD-01).
A31: Tiempo de contacto diario (s) | B31: =Orbita!$B$29*Orbita!$B$30 -> 600 | C31: =Orbita!$C$29*Orbita!$C$30 -> 360
A33: Oportunidades de captura sobre zonas cafeteras
A34: Parámetro | B34: Valor | C34: Unidad | D34: Nota / fuente
A35: Inclinación máxima fuera de nadir | B35: 30 | C35: ° | D35: RF-21.
A36: Ancho este–oeste de la franja cafetera | B36: 500 | C36: km | D36: S-12, estimación sobre mapa.
A37: Elevación del satélite vista desde el objetivo | B37: =DEGREES(ACOS(SIN(RADIANS(Orbita!$B$35))*Orbita!$B$8/Orbita!$B$5)) -> 57.103923 | C37: ° | D37: cos ε = sin η · a/R_E
A38: Ángulo central a la inclinación máxima | B38: =90-Orbita!$B$35-Orbita!$B$37 -> 2.8960773 | C38: °
A39: Desplazamiento lateral en tierra | B39: =Orbita!$B$5*RADIANS(Orbita!$B$38) -> 322.38292 | C39: km
A40: Distancia oblicua a la inclinación máxima | B40: =Orbita!$B$5*SIN(RADIANS(Orbita!$B$38))/SIN(RADIANS(Orbita!$B$35)) -> 644.49133 | C40: km | D40: Se usa para la GSD fuera de nadir.
A41: Ancho de barrido | B41: =Camara_Datos!$B$13 -> 111.03086 | C41: km | D41: Viene de Camara_Datos.
A42: Ancho accesible | B42: =Orbita!$B$36+Orbita!$B$41+2*Orbita!$B$39 -> 1255.7967 | C42: km | D42: Franja + barrido + 2 × desplazamiento.
A43: Oportunidades diurnas por día | B43: =Orbita!$B$42/Orbita!$B$17 -> 0.4717869 | C43: 1/día | D43: Solo una dirección de traza es diurna (nodo 10:30).
...

Sheet Camara_Datos
A1: Carga útil, volumen de datos y almacenamiento
A2: Diseño de referencia: sensor monocromático + filtro de 4 franjas (push-frame).
A4: Parámetro | B4: Valor | C4: Unidad | D4: Nota / fuente
A5: Tamaño de píxel p | B5: 3.45 | C5: µm | D5: Diseño de referencia (definir sensor en P4).
A6: Distancia focal f | B6: 35 | C6: mm | D6: Lente comercial (S-08).
A7: Píxeles por lado (ventana usada) | B7: 2048 | C7: px
A8: Profundidad de bits | B8: 12 | C8: bit | D8: ET-04.
A9: Número de franjas (bandas) | B9: 4 | C9: – | D9: RF-01.
A10: GSD en nadir | B10: =Camara_Datos!$B$5*0.000001*Orbita!$B$6*1000/(Camara_Datos!$B$6*0.001) -> 54.214286 | C10: m | D10: GSD = p·h/f. Límite 60 m (ET-02).
A11: GSD a lo largo de la traza a la inclinación máxima | B11: =Camara_Datos!$B$10*Orbita!$B$40/Orbita!$B$6 -> 63.528431 | C11: m | D11: Escala con la distancia oblicua.
A12: GSD a lo ancho de la traza a la inclinación máxima | B12: =Camara_Datos!$B$11/SIN(RADIANS(Orbita!$B$37)) -> 75.659974 | C12: m | D12: Proyección sobre el terreno. Límite 80 m.
A13: Ancho de barrido | B13: =Camara_Datos!$B$7*Camara_Datos!$B$10/1000 -> 111.03086 | C13: km | D13: Límite ≥ 80 km (ET-03).
A14: Longitud de cada franja en tierra | B14: =Camara_Datos!$B$7/Camara_Datos!$B$9*Camara_Datos!$B$10/1000 -> 27.757714 | C14: km
A15: Intervalo máximo entre cuadros | B15: =Camara_Datos!$B$14/Orbita!$B$13 -> 3.9750458 | C15: s | D15: Para no dejar huecos en ninguna banda (ET-06).
A16: Intervalo nominal entre cuadros | B16: 3.5 | C16: s | D16: Debe ser menor que el máximo.
A17: Avance entre cuadros | B17: =Camara_Datos!$B$16*Orbita!$B$13 -> 24.440473 | C17: km
A18: Tiempo de exposición máximo | B18: 2 | C18: ms | D18: ET-05.
A19: Borrosidad por movimiento | B19: =Orbita!$B$13*1000*Camara_Datos!$B$18/1000/Camara_Datos!$B$10 -> 0.25760709 | C19: píxeles | D19: Debe ser < 0,5 píxel.
A21: Volumen por escena
A22: Parámetro | B22: Valor | C22: Unidad | D22: Nota / fuente
A23: Longitud de escena | B23: 250 | C23: km | D23: RNF-04.
A24: Cuadros por escena | B24: =ROUNDUP((Camara_Datos!$B$23+Camara_Datos!$B$13)/Camara_Datos!$B$17,0)+1 -> 16 | C24: – | D24: Cubrir la escena con las 4 franjas.
A25: Tamaño de un cuadro | B25: =Camara_Datos!$B$7^2*Camara_Datos!$B$8/8/1000000 -> 6.291456 | C25: MB
A26: Escena sin comprimir | B26: =Camara_Datos!$B$24*Camara_Datos!$B$25 -> 100.6633 | C26: MB
A27: Razón de compresión sin pérdidas | B27: 2 | C27: :1 | D27: TBD-02 (CCSDS 123).
A28: Escena comprimida | B28: =Camara_Datos!$B$26/Camara_Datos!$B$27 -> 50.331648 | C28: MB
A29: Factor de reducción de vistas previas | B29: 64 | C29: × | D29: Reducción 8 × 8.
A30: Vista previa por escena | B30: =Camara_Datos!$B$28/Camara_Datos!$B$29 -> 0.786432 | C30: MB
A31: Metadatos por escena | B31: =Camara_Datos!$B$24*1 -> 16 | C31: kB | D31: ≈1 kB por cuadro.
A32: Tasa de lectura cámara → OBC requerida | B32: =Camara_Datos!$B$7^2/0.5/1000000 -> 8.388608 | C32: Mpx/s | D32: Cuadro en < 0,5 s. ET-08 pide ≥ 10.
A33: RAM para dos cuadros | B33: =2*Camara_Datos!$B$25 -> 12.582912 | C33: MB | D33: ET-09: ≥ 16 MB; se propone 32 MB.
A34: Tasa de escritura sostenida | B34: =Camara_Datos!$B$25/Camara_Datos!$B$16 -> 1.7975589 | C34: MB/s | D34: ET-11 pide ≥ 4 MB/s (margen ×2).
A36: Operación y volumen diario
A37: Parámetro | B37: Valor | C37: Unidad | D37: Nota / fuente
A38: Escenas por semana (dimensionamiento) | B38: 3.5 | C38: 1/semana | D38: Algo por encima del máximo de Orbita (lado seguro).
A39: Duración de la misión | B39: 182 | C39: días | D39: ≈ 6 meses.
A40: Escenas en toda la misión | B40: =Camara_Datos!$B$38*Camara_Datos!$B$39/7 -> 91 | C40: –
A41: Tamaño de una muestra de telemetría | B41: 200 | C41: B
A42: Periodo de muestreo de telemetría | B42: 60 | C42: s | D42: ET-14.
A43: Telemetría diaria | B43: =86400/Camara_Datos!$B$42*Camara_Datos!$B$41/1000000 -> 0.288 | C43: MB/día
...

Sheet Enlaces
A1: Presupuestos de enlace
A2: C/N0 = PIRE − L_el − L_otras + G/T + 228,6 dB
A4: Parámetro | B4: UHF bajada | C4: S bajada | D4: UHF subida | E4: Nota / fuente
A5: Frecuencia (MHz) | B5: 437 | C5: 2250 | D5: 437 | E5: UHF 435–438 MHz; S 2200–2290 MHz.
A6: Distancia (km) | B6: =Orbita!$B$24 -> 1815.6412 | C6: =Orbita!$C$24 -> 1293.7683 | D6: =Orbita!$B$24 -> 1815.6412 | E6: Desde Orbita (elevación mínima de cada enlace).
A7: Potencia TX (W) | B7: 1 | C7: 1 | D7: 25 | E7: Satélite 1 W; estación 25 W.
A8: Potencia TX (dBW) | B8: =10*LOG10(B7) -> 0 | C8: =10*LOG10(C7) -> 0 | D8: =10*LOG10(D7) -> 13.9794
A9: Pérdidas de línea TX (dB) | B9: 0.5 | C9: 1 | D9: 2
A10: Ganancia antena TX (dBi) | B10: 0 | C10: 1 | D10: 14 | E10: Parche S a ~60° de su eje si el satélite apunta a nadir.
A11: PIRE (dBW) | B11: =B8-B9+B10 -> -0.5 | C11: =C8-C9+C10 -> 0 | D11: =D8-D9+D10 -> 25.9794
A12: Pérdida por espacio libre (dB) | B12: =32.45+20*LOG10(B5)+20*LOG10(B6) -> 150.44023 | C12: =32.45+20*LOG10(C5)+20*LOG10(C6) -> 161.73078 | D12: =32.45+20*LOG10(D5)+20*LOG10(D6) -> 150.44023 | E12: FSPL = 32,45 + 20log f[MHz] + 20log d[km]
A13: Polarización, atmósfera y apuntamiento (dB) | B13: 4.5 | C13: 2 | D13: 4.5 | E13: Incluye 3 dB de polarización lineal–circular en UHF.
A14: Diámetro de parábola de la estación (m) | B14: – | C14: 2.4 | D14: – | E14: S-02.
A15: Eficiencia de apertura | B15: – | C15: 0.55 | D15: –
A16: Ganancia antena RX (dBi) | B16: 14 | C16: =10*LOG10(C15*(PI()*C14/(300/C5))^2) -> 32.452074 | D16: 0 | E16: UHF: Yagi cruzada 14 dBi; S: parábola; subida: antena del satélite.
A17: Pérdidas de línea RX (dB) | B17: 0 | C17: 0 | D17: 0.5
A18: Temperatura de ruido del sistema (K) | B18: 600 | C18: 200 | D18: 730 | E18: UHF urbano 600 K; S 200 K; satélite mira a la Tierra.
A19: G/T del receptor (dB/K) | B19: =B16-B17-10*LOG10(B18) -> -13.781513 | C19: =C16-C17-10*LOG10(C18) -> 9.4417745 | D19: =D16-D17-10*LOG10(D18) -> -29.133229
A20: C/N0 (dBHz) | B20: =B11-B12-B13+B19+228.6 -> 59.378258 | C20: =C11-C12-C13+C19+228.6 -> 74.310994 | D20: =D11-D12-D13+D19+228.6 -> 70.505942
A21: Tasa de datos (kbit/s) | B21: 9.6 | C21: =Camara_Datos!$B$50*1000 -> 2000 | D21: 9.6 | E21: La tasa de S viene de Camara_Datos.
A22: Eb/N0 disponible (dB) | B22: =B20-10*LOG10(B21*1000) -> 19.555546 | C22: =C20-10*LOG10(C21*1000) -> 11.300694 | D22: =D20-10*LOG10(D21*1000) -> 30.68323
A23: Eb/N0 requerido + pérdidas de implementación (dB) | B23: 14 | C23: 7 | D23: 14 | E23: GFSK no coherente BER 1e-5; S: QPSK + convolucional r=1/2 (5 dB) + 2 dB.
A24: Margen (dB) | B24: =B22-B23 -> 5.555546 | C24: =C22-C23 -> 4.3006944 | D24: =D22-D23 -> 16.68323 | E24: RNF-07 exige ≥ 3 dB.
A25: ¿Cumple RNF-07? | B25: =IF(B24>=3,"Sí","No") -> Sí | C25: =IF(C24>=3,"Sí","No") -> Sí | D25: =IF(D24>=3,"Sí","No") -> Sí
A27: Capacidad UHF diaria
A28: Tiempo de contacto UHF (s/día) | B28: =Orbita!$B$31 -> 600
A29: Volumen UHF útil (kB/día, eficiencia 60 %) | B29: =B28*9.6*0.6/8 -> 432 | E29: Muy por debajo de lo que generan las imágenes: por eso se necesita banda S.

Sheet Potencia_Masa
A1: Presupuesto de potencia, energía, batería, masa y volumen
A4: Parámetro | B4: Valor | C4: Unidad | D4: Nota / fuente
A5: Área de celda | B5: 30.2 | C5: cm² | D5: Celda triple unión típica ~40×80 mm.
A6: Eficiencia de celda (BOL) | B6: 0.28 | C6: – | D6: Conservador para GaAs triple unión.
A7: Constante solar | B7: 1361 | C7: W/m²
A8: Potencia por celda | B8: =Potencia_Masa!$B$7*Potencia_Masa!$B$5/10000*Potencia_Masa!$B$6 -> 1.1508616 | C8: W
A9: Factor por temperatura | B9: 0.92 | C9: –
A10: Factor por degradación (6 meses) | B10: 0.98 | C10: –
A11: Eficiencia MPPT | B11: 0.9 | C11: –
A12: Factor de cableado y empaque | B12: 0.97 | C12: –
A13: Celdas por cara | B13: 2 | C13: –
A14: Potencia útil por cara a incidencia normal | B14: =Potencia_Masa!$B$8*Potencia_Masa!$B$13*Potencia_Masa!$B$9*Potencia_Masa!$B$10*Potencia_Masa!$B$11*Potencia_Masa!$B$12 -> 1.811679 | C14: W
A15: Caras equivalentes en apuntamiento solar (esquina) | B15: =SQRT(3) -> 1.7320508 | C15: – | D15: Tres caras a 54,7°.
A16: Factor por error de apuntamiento | B16: 0.95 | C16: – | D16: Apuntamiento solar con magnetorquers.
A17: Potencia en luz solar | B17: =Potencia_Masa!$B$14*Potencia_Masa!$B$15*Potencia_Masa!$B$16 -> 2.981024 | C17: W
A18: Potencia media orbital | B18: =Potencia_Masa!$B$17*Orbita!$B$16 -> 1.8711603 | C18: W | D18: ET-22 pide ≥ 1,80 W.
A19: Pérdida por modos de apuntamiento a la Tierra | B19: 0.5 | C19: Wh/día | D19: Adquisiciones y pases.
A20: Energía generada por día | B20: =Potencia_Masa!$B$18*24-Potencia_Masa!$B$19 -> 44.407848 | C20: Wh/día
A22: Consumo por subsistema
A23: Subsistema | B23: P nominal (W) | C23: P máxima (W) | D23: Ciclo de actividad | E23: Energía (Wh/día) | F23: Masa (kg) | G23: Volumen asignado | H23: Fuente de la estimación
A24: OBC: MCU, SDRAM, almacenamiento | B24: 0.4 | C24: 0.9 | D24: 1 | E24: =B24*D24*24 -> 9.6 | F24: 0.06 | G24: PCB-2, 12 mm | H24: Hojas de datos típicas Cortex-M7
A25: Sensores de orientación | B25: 0.15 | C25: 0.2 | D25: 1 | E25: =B25*D25*24 -> 3.6 | F25: 0 | G25: PCB-2 y paneles | H25: Rangos típicos (NASA SoA)
A26: Magnetorquers | B26: 0.45 | C26: 0.45 | D26: 0.33 | E26: =B26*D26*24 -> 3.564 | F26: 0.06 | G26: Bahía inferior | H26: 3 × 5 V × 30 mA
A27: Ruedas de reacción | B27: 0.3 | C27: 1.2 | D27: 0.06 | E27: =B27*D27*24 -> 0.432 | F27: 0.15 | G27: Bahía inferior | H27: Rangos típicos (NASA SoA)
A28: EPS: control y reposo (incluye 2 celdas 18650) | B28: 0.15 | C28: 0.2 | D28: 1 | E28: =B28*D28*24 -> 3.6 | F28: 0.18 | G28: PCB-1, 25 mm
A29: Calefactor de batería | B29: 0.5 | C29: 0.5 | D29: 0.2 | E29: =B29*D29*24 -> 2.4 | F29: 0 | G29: PCB-1 | H29: Supuesto (TBD-04)
A30: UHF en recepción | B30: 0.25 | C30: 0.3 | D30: 1 | E30: =B30*D30*24 -> 6 | F30: 0.13 | G30: PCB-3, 15 mm | H30: Transceptor + LNA + MCU
A31: UHF en transmisión | B31: 2 | C31: 2.5 | D31: 0.04 | E31: =B31*D31*24 -> 1.92 | F31: 0 | G31: PCB-3 | H31: PA ≈ 50 % de eficiencia
A32: TX banda S | B32: 6 | C32: 8 | D32: =10/1440 -> 0.0069444444 | E32: =B32*D32*24 -> 1 | F32: 0 | G32: PCB-3 | H32: Rangos típicos; 10 min/día
A33: Cámara (sensor + electrónica) | B33: 1.5 | C33: 2 | D33: =2.5/1440 -> 0.0017361111 | E33: =B33*D33*24 -> 0.0625 | F33: 0.2 | G33: Bahía inferior, 40 mm | H33: 5 min cada 2 días
A34: Subtotal de cargas | E34: =SUM(E24:E33) -> 32.1785
A35: Pérdidas de conversión y batería | D35: 0.12 | E35: =E34*D35 -> 3.86142 | H35: Convertidores ≈ 88 %
A36: Estructura, paneles, antenas, cableado | F36: =0.12+0.2+0.12+0.08 -> 0.52 | G36: Externo | H36: 0,12 + 0,20 + 0,12 + 0,08 kg
A37: Consumo total | E37: =E34+E35 -> 36.03992 | F37: =SUM(F24:F36) -> 1.3
A38: Consumo medio orbital (W) | E38: =Potencia_Masa!$E$37/24 -> 1.5016633
A39: Energía generada (Wh/día) | E39: =Potencia_Masa!$B$20 -> 44.407848
A40: Margen de energía | E40: =Potencia_Masa!$B$20/Potencia_Masa!$E$37-1 -> 0.23218497 | H40: RNF-08 exige ≥ 20 %.
A41: ¿Cumple RNF-08? | E41: =IF(Potencia_Masa!$E$40>=0.2,"Sí","No") -> Sí
A43: Batería y peor eclipse
A44: Parámetro | B44: Valor | C44: Unidad | D44: Nota / fuente
...

Sheet Procesamiento
A1: Carga de procesamiento y memoria
A4: Parámetro | B4: Valor | C4: Unidad | D4: Nota / fuente
A5: Frecuencia de referencia del procesador | B5: 200 | C5: MHz | D5: Mínimo de ET-12.
A7: Tarea | B7: Tasa (Hz) | C7: kciclos por ejecución | D7: Mciclos/s | E7: Carga | F7: Nota
A8: Sensores + filtro de actitud | B8: 10 | C8: 300 | D8: =B8*C8/1000 -> 3 | E8: =D8/Procesamiento!$B$5 -> 0.015 | F8: EKF de orden bajo
A9: Ley de control | B9: 10 | C9: 20 | D9: =B9*C9/1000 -> 0.2 | E9: =D9/Procesamiento!$B$5 -> 0.001
A10: SGP4 + IGRF + posición del Sol | B10: 1 | C10: 400 | D10: =B10*C10/1000 -> 0.4 | E10: =D10/Procesamiento!$B$5 -> 0.002
A11: Telemetría, comandos, CAN | B11: 1 | C11: 2000 | D11: =B11*C11/1000 -> 2 | E11: =D11/Procesamiento!$B$5 -> 0.01 | F11: Agregado
A12: Captura y escritura (durante escena) | B12: 1 | C12: 20000 | D12: =B12*C12/1000 -> 20 | E12: =D12/Procesamiento!$B$5 -> 0.1 | F12: Temporal
A13: Entramado banda S (durante pase) | B13: 1 | C13: 5000 | D13: =B13*C13/1000 -> 5 | E13: =D13/Procesamiento!$B$5 -> 0.025 | F13: 2 Mbit/s × 20 ciclos/byte
A14: Carga continua (primeras 4 tareas) | D14: =SUM(D8:D11) -> 5.6 | E14: =D14/Procesamiento!$B$5 -> 0.028
A15: Carga pico (todas) | D15: =SUM(D8:D13) -> 30.6 | E15: =D15/Procesamiento!$B$5 -> 0.153
A17: Compresión fuera de línea
A18: Parámetro | B18: Valor | C18: Unidad | D18: Nota / fuente
A19: Ciclos por muestra (CCSDS 123, software) | B19: 500 | C19: ciclos | D19: Estimación de orden de magnitud.
A20: Muestras por escena | B20: =Camara_Datos!$B$24*Camara_Datos!$B$7^2 -> 67108864 | C20: muestras
A21: Tiempo de compresión por escena | B21: =Procesamiento!$B$20*Procesamiento!$B$19/(Procesamiento!$B$5*1000000) -> 167.77216 | C21: s | D21: Se hace entre pases.
A23: Memoria
A24: Parámetro | B24: Valor | C24: Unidad | D24: Nota / fuente
A25: RAM externa mínima | B25: =Camara_Datos!$B$33 -> 12.582912 | C25: MB | D25: Dos cuadros; se propone 32 MB.
A26: RAM interna (RTOS, pilas, buffers, filtro) | B26: 0.2 | C26: MB | D26: Estimación; ≥ 0,5 MB recomendado.
A27: Programa (por ranura) | B27: 1 | C27: MB | D27: 2 ranuras + respaldo en NOR.
A28: Almacenamiento masivo | B28: =Camara_Datos!$B$67 -> 1.5314538 | C28: GB | D28: Desde Camara_Datos.

Sheet Matrices
A1: Criterios, pesos y matrices de decisión
A2: Calificaciones de 1 (malo) a 5 (muy bueno). Total = SUMPRODUCT(pesos, calificaciones).
A4: Criterio | B4: Peso | F4: Por qué este peso
A5: C1 Consumo de energía | B5: 0.2 | F5: El margen de energía es de solo ~23 %.
A6: C2 Confiabilidad y tolerancia a fallas | B6: 0.2 | F6: El satélite no se puede reparar.
A7: C3 Desempeño frente a requisitos | B7: 0.2 | F7: Hay requisitos de desempeño al límite.
A8: C4 Volumen y masa | B8: 0.15 | F8: Quedan pocos milímetros en la pila.
A9: C5 Complejidad y riesgo técnico | B9: 0.15 | F9: Tiempo del curso limitado.
A10: C6 Integración y prueba | B10: 0.1 | F10: Integración entre tres parejas en P6.
A11: Suma de pesos | B11: =SUM(B5:B10) -> 1
A13: D1. Organización del procesamiento
A14: Criterio | B14: Peso | C14: A: centralizado | D14: B: semidistribuido | E14: C: distribuido | F14: Justificación
A15: C1 Consumo de energía | B15: =B5 -> 0.2 | C15: 5 | D15: 4 | E15: 3 | F15: Cada MCU supervisor suma ~30 mW; C agrega FPGA.
A16: C2 Confiabilidad y tolerancia a fallas | B16: =B6 -> 0.2 | C16: 2 | D16: 4 | E16: 4 | F16: En A, si el OBC se cuelga nadie protege la batería ni reinicia.
A17: C3 Desempeño frente a requisitos | B17: =B7 -> 0.2 | C17: 4 | D17: 4 | E17: 5 | F17: Los tres cumplen; C sobra en capacidad.
A18: C4 Volumen y masa | B18: =B8 -> 0.15 | C18: 5 | D18: 4 | E18: 2 | F18: C requiere más área de PCB.
A19: C5 Complejidad y riesgo técnico | B19: =B9 -> 0.15 | C19: 4 | D19: 3 | E19: 2 | F19: B: protocolos entre MCU; C: además FPGA.
A20: C6 Integración y prueba | B20: =B10 -> 0.1 | C20: 2 | D20: 4 | E20: 3 | F20: En B cada tarjeta se prueba sola (RNF-14).
A21: Total ponderado | B21: =SUM(B15:B20) -> 1 | C21: =SUMPRODUCT($B$15:$B$20,C15:C20) -> 3.75 | D21: =SUMPRODUCT($B$15:$B$20,D15:D20) -> 3.85 | E21: =SUMPRODUCT($B$15:$B$20,E15:E20) -> 3.3
A22: Seleccionada | C22: =INDEX(C14:E14,MATCH(MAX(C21,D21,E21),C21:E21,0)) -> B: semidistribuido
A24: D2. Tecnología del OBC
A25: Criterio | B25: Peso | C25: A: MCU Cortex-M7 | D25: B: Cortex-A con Linux | E25: C: MCU + FPGA | F25: Justificación
A26: C1 Consumo de energía | B26: =B5 -> 0.2 | C26: 5 | D26: 1 | E26: 3 | F26: Linux consume 1,5–3 W.
A27: C2 Confiabilidad y tolerancia a fallas | B27: =B6 -> 0.2 | C27: 4 | D27: 2 | E27: 3 | F27: DDR y sistema de archivos más frágiles; arranque largo.
A28: C3 Desempeño frente a requisitos | B28: =B7 -> 0.2 | C28: 4 | D28: 5 | E28: 5 | F28: La carga de CPU es baja (hoja Procesamiento).
A29: C4 Volumen y masa | B29: =B8 -> 0.15 | C29: 5 | D29: 4 | E29: 3
A30: C5 Complejidad y riesgo técnico | B30: =B9 -> 0.15 | C30: 4 | D30: 2 | E30: 2 | F30: DDR y BGA difíciles de enrutar.
A31: C6 Integración y prueba | B31: =B10 -> 0.1 | C31: 4 | D31: 3 | E31: 3
A32: Total ponderado | B32: =SUM(B26:B31) -> 1 | C32: =SUMPRODUCT($B$26:$B$31,C26:C31) -> 4.35 | D32: =SUMPRODUCT($B$26:$B$31,D26:D31) -> 2.8 | E32: =SUMPRODUCT($B$26:$B$31,E26:E31) -> 3.25
A33: Seleccionada | C33: =INDEX(C25:E25,MATCH(MAX(C32,D32,E32),C32:E32,0)) -> A: MCU Cortex-M7
A35: D3. División en PCBs
A36: Criterio | B36: Peso | C36: A: 2 PCBs | D36: B: 4 PCBs | E36: C: 6 PCBs | F36: Justificación
A37: C1 Consumo de energía | B37: =B5 -> 0.2 | C37: 4 | D37: 4 | E37: 4 | F37: Casi no cambia.
A38: C2 Confiabilidad y tolerancia a fallas | B38: =B6 -> 0.2 | C38: 3 | D38: 4 | E38: 4 | F38: En A conviven RF, potencia y digital rápido.
A39: C3 Desempeño frente a requisitos | B39: =B7 -> 0.2 | C39: 4 | D39: 4 | E39: 4 | F39: Todas cumplen.
A40: C4 Volumen y masa | B40: =B8 -> 0.15 | C40: 5 | D40: 4 | E40: 1 | F40: C no cabe en 96 mm.
A41: C5 Complejidad y riesgo técnico | B41: =B9 -> 0.15 | C41: 3 | D41: 4 | E41: 3 | F41: A muy densa; C multiplica conectores.
A42: C6 Integración y prueba | B42: =B10 -> 0.1 | C42: 2 | D42: 4 | E42: 5 | F42: Más tarjetas = pruebas por partes.
A43: Total ponderado | B43: =SUM(B37:B42) -> 1 | C43: =SUMPRODUCT($B$37:$B$42,C37:C42) -> 3.6 | D43: =SUMPRODUCT($B$37:$B$42,D37:D42) -> 4 | E43: =SUMPRODUCT($B$37:$B$42,E37:E42) -> 3.5
A44: Seleccionada | C44: =INDEX(C36:E36,MATCH(MAX(C43,D43,E43),C43:E43,0)) -> B: 4 PCBs
...

Sheet Requisitos
A1: Matriz de requisitos y criterios de aceptación
A2: Copiado del informe; mantener sincronizado.
A4: ID | B4: Tipo | C4: Requisito | D4: Origen o justificación | E4: Prioridad | F4: Criterio de aceptación
A5: Carga útil y datos de misión
A6: RF-01 | B6: Func. | C6: El satélite deberá capturar imágenes de la superficie terrestre en al menos cuatro bandas espectrales, incluyendo una en el rojo y otra en el infrarrojo cercano. | D6: Misión. El contraste rojo–NIR es la base de los índices de vegetación. | E6: Alta | F6: [A, I] Curvas de respuesta de sensor y filtros muestran ≥4 bandas con rojo y NIR (ET-01).
A7: RF-02 | B7: Func. | C7: El satélite deberá ejecutar adquisiciones programadas desde tierra para instantes o coordenadas definidos. | D7: Misión: las zonas cafeteras son regiones concretas. | E7: Alta | F7: [D] En mesa, un comando con marca de tiempo dispara la captura en el instante programado con error ≤1 s.
A8: RF-03 | B8: Func. | C8: Cada imagen deberá quedar asociada a su hora, posición estimada, actitud y temperatura del sensor. | D8: Georreferenciación y corrección radiométrica en tierra. | E8: Alta | F8: [I] El formato de archivo contiene los campos; [D] se verifican en una captura de prueba.
A9: RF-04 | B9: Func. | C9: El satélite deberá conservar las imágenes a bordo hasta que tierra confirme su recepción. | D9: Evitar pérdidas por pases fallidos. | E9: Alta | F9: [D] Ninguna imagen se borra sin el comando de confirmación.
A10: RF-05 | B10: Func. | C10: El satélite deberá transmitir las imágenes a la estación terrena de Medellín. | D10: Enunciado. | E10: Alta | F10: [A] Presupuesto de enlace con margen ≥3 dB (ET-21).
A11: RF-06 | B11: Func. | C11: El satélite deberá generar versiones reducidas de las imágenes para que el operador decida cuáles descargar completas. | D11: La nubosidad en la zona andina es alta; no vale la pena bajar escenas nubladas. | E11: Media | F11: [D] El comando de vista previa produce un archivo reducido de la escena indicada.
A12: Comunicaciones y operación
A13: RF-07 | B13: Func. | C13: El satélite deberá recibir telecomandos desde tierra y ejecutarlos de forma inmediata o programada. | D13: Enunciado. | E13: Alta | F13: [A] Margen de subida ≥3 dB; [D] ejecución inmediata y diferida en mesa.
A14: RF-08 | B14: Func. | C14: El satélite deberá transmitir telemetría de tensiones, corrientes, temperaturas, modo de operación y estado de cada subsistema. | D14: Enunciado. | E14: Alta | F14: [I] La lista de telemetría cubre todos los subsistemas y líneas de potencia.
A15: RF-09 | B15: Func. | C15: El satélite deberá emitir una baliza periódica con telemetría básica sin necesidad de un comando previo. | D15: Permite encontrarlo tras el despliegue y operar en modo seguro. | E15: Alta | F15: [D] Baliza cada ≤30 s una vez cumplido RN-04.
A16: RF-10 | B16: Func. | C16: El satélite deberá entrar en un modo seguro ante batería baja o falla de un subsistema, manteniendo la baliza y la recepción de comandos. | D16: Supervivencia sin intervención de tierra. | E16: Alta | F16: [D] Con tensión de batería simulada bajo el umbral, se apagan las cargas no esenciales y la baliza continúa.
A17: RF-11 | B17: Func. | C17: El satélite deberá detectar el bloqueo del computador central y reiniciarlo de forma autónoma, y tierra deberá poder reiniciarlo aunque este no responda. | D17: Recuperación de bloqueos por radiación o errores de software. | E17: Alta | F17: [P] Al detener el refresco del watchdog hay reinicio; el comando de reinicio por hardware funciona con el OBC detenido.
A18: RF-12 | B18: Func. | C18: El satélite deberá permitir actualizar parámetros y software de vuelo desde tierra, conservando una versión de respaldo. | D18: Corregir errores en órbita sin perder el satélite. | E18: Media | F18: [D] Carga de una versión nueva y retorno automático a la de respaldo si falla.
A19: RF-13 | B19: Func. | C19: Deberá ser posible cargar la batería, programar y diagnosticar los subsistemas con el satélite ensamblado. | D19: Integración y pruebas (Práctica 6). | E19: Media | F19: [I] Puerto de acceso alcanzable con la estructura cerrada.
A20: Potencia
A21: RF-14 | B21: Func. | C21: El satélite deberá generar energía eléctrica a partir de la radiación solar y almacenarla. | D21: Enunciado. | E21: Alta | F21: [A] Balance energético (ET-22, ET-23).
A22: RF-15 | B22: Func. | C22: El satélite deberá encender y apagar por comando la alimentación de cada subsistema de forma independiente. | D22: Gestión de energía y aislamiento de fallas. | E22: Alta | F22: [D] Cada línea conmutada responde a su comando sin afectar a las demás.
A23: RF-16 | B23: Func. | C23: El satélite deberá medir tensión y corriente de la batería, de cada entrada solar y de cada línea de distribución. | D23: Enunciado: supervisar el consumo. | E23: Alta | F23: [P] Comparación contra instrumento patrón con error ≤2 %.
A24: RF-17 | B24: Func. | C24: El satélite deberá cortar una línea de distribución ante sobrecorriente y permitir su reconexión. | D24: Enunciado: proteger los circuitos; latch-up (RA-06). | E24: Alta | F24: [P] Con sobrecarga simulada, la línea se corta en ≤1 ms y se reconecta.
A25: RF-18 | B25: Func. | C25: El satélite deberá proteger la batería contra sobrecarga, sobredescarga, sobrecorriente y carga fuera del rango de temperatura permitido. | D25: Seguridad y vida útil de la batería. | E25: Alta | F25: [P] Ensayo en banco de cada condición.
A26: Orientación
A27: RF-19 | B27: Func. | C27: El satélite deberá estimar su actitud a partir de mediciones a bordo. | D27: Enunciado. | E27: Alta | F27: [A] Error de determinación ≤1° con luz solar (ET-28).
A28: RF-20 | B28: Func. | C28: El satélite deberá reducir su velocidad angular después de la separación. | D28: Rotación inicial (S-09). | E28: Alta | F28: [A] Simulación simple o cálculo de tiempo de estabilización (ET-30).
A29: RF-21 | B29: Func. | C29: Durante una adquisición, el satélite deberá orientar la cámara hacia la región objetivo, con inclinación respecto a nadir de hasta 30°. | D29: Enunciado; revisita (el informe). | E29: Alta | F29: [A] ET-29 y ET-32.
A30: RF-22 | B30: Func. | C30: Fuera de adquisiciones y pases, el satélite deberá orientarse para favorecer la generación eléctrica. | D30: Enunciado. | E30: Media | F30: [A] El balance energético se cumple con el modo de apuntamiento solar.
A31: RF-23 | B31: Func. | C31: El satélite deberá conocer su posición orbital y el tiempo UTC con la exactitud necesaria para programar capturas y apuntar. | D31: Sin posición no se puede calcular el vector a la región objetivo. | E31: Alta | F31: [A] ET-33 y ET-34.
A32: No funcionales
A33: RNF-01 | B33: No func. | C33: La distancia de muestreo en tierra (GSD) deberá ser ≤60 m en nadir y ≤80 m a 30° de inclinación. | D33: Escala de lote y región: un lote de 10 ha ocupa unos 5×5 píxeles. | E33: Alta | F33: [A] GSD=p h/f con datos de sensor y lente (ET-02).
A34: RNF-02 | B34: No func. | C34: El ancho de barrido deberá ser ≥80 km. | D34: Cubrir en una pasada una región cafetera como el Eje Cafetero (estimación sobre mapa). | E34: Alta | F34: [A] ET-03.
A35: RNF-03 | B35: No func. | C35: La resolución radiométrica deberá ser ≥10 bit. | D35: Diferencias pequeñas de reflectancia en vegetación. | E35: Media | F35: [I] Hoja de datos del sensor.
A36: RNF-04 | B36: No func. | C36: El sistema deberá poder adquirir, almacenar y bajar hasta 3,5 escenas por semana de 250 km× barrido. | D36: Algo por encima del máximo geométrico (≈3,3/semana) con ±30° (el informe). | E36: Alta | F36: [A] Presupuestos de datos y energía.
A37: RNF-05 | B37: No func. | C37: El almacenamiento a bordo deberá contener al menos 10 escenas sin comprimir. | D37: Unas tres semanas sin descarga. | E37: Alta | F37: [A, I] ET-10.
A38: RNF-06 | B38: No func. | C38: La capacidad diaria de descarga deberá ser ≥2 veces el volumen medio generado. | D38: Pases perdidos, reintentos, telemetría. | E38: Alta | F38: [A] Presupuesto de datos.
A39: RNF-07 | B39: No func. | C39: Todos los enlaces deberán tener margen ≥3 dB a su elevación mínima. | D39: Práctica usual en presupuestos de enlace. | E39: Alta | F39: [A] la tabla del informe.
A40: RNF-08 | B40: No func. | C40: El balance energético diario deberá ser positivo con margen ≥20 % en operación nominal. | D40: Incertidumbre de las estimaciones. | E40: Alta | F40: [A] la tabla del informe.
A41: RNF-09 | B41: No func. | C41: La profundidad de descarga de la batería deberá ser ≤20 % en el peor eclipse. | D41: ≈2700 ciclos en seis meses. | E41: Alta | F41: [A] ET-23.
...

Sheet Especificaciones
A1: Especificaciones técnicas
A2: Copiado del informe; mantener sincronizado.
A4: ID | B4: Requisitos asociados | C4: Parámetro técnico | D4: Valor, rango o tolerancia | E4: Unidad | F4: Fundamento | G4: Verificación
A5: ET-01 | B5: RF-01 | C5: Centro / ancho de banda | D5: 560/35; 665/30; 705/15; 842/115 (±10 nm en el centro) | E5: nm | F5: Cercanas a B3, B4, B5 y B8 de Sentinel-2 para poder compararlas. | G5: A, I
A6: ET-02 | B6: RNF-01 | C6: GSD | D6: ≤60 nadir, ≤80 a 30° (diseño de ref.: 54,2) | E6: m | F6: GSD=p h/f. | G6: A
A7: ET-03 | B7: RNF-02 | C7: Ancho de barrido | D7: ≥80 (diseño de ref.: 111) | E7: km | F7: 2048×54,2 m. | G7: A
A8: ET-04 | B8: RNF-03 | C8: Cuantización | D8: 12 | E8: bit | F8: ≥10 más margen para ajuste de ganancia. | G8: I
A9: ET-05 | B9: RNF-11 | C9: Tiempo de exposición máximo | D9: ≤2 | E9: ms | F9: Borrosidad =7,0 km/s×2 ms=14 m≈0,26 GSD. | G9: A
A10: ET-06 | B10: RNF-04 | C10: Intervalo entre cuadros | D10: ≤3,9 (nominal 3,5) | E10: s | F10: Cada franja del filtro cubre 512 filas ×54,2 m=27,7 km; a 7 km/s se necesita un cuadro cada 3,9 s o menos para no dejar huecos. | G10: A
A11: ET-07 | B11: RNF-04, RNF-05 | C11: Datos por escena | D11: 100,7 sin comprimir; ≈50 comprimido | E11: MB | F11: 16 cuadros de 6,29 MB (2048^2×12 bit); compresión 2:1 (TBD-02). | G11: A
A12: ET-08 | B12: RF-01, RNF-04 | C12: Tasa de lectura cámara–OBC | D12: ≥10 | E12: Mpx/s | F12: Leer un cuadro de 4,19 Mpx en menos de 0,5 s. | G12: A, P
A13: ET-09 | B13: RNF-04 | C13: RAM para cuadros | D13: ≥16 (se propone 32) | E13: MB | F13: Dos cuadros en memoria (2×6,29 MB) para capturar uno mientras se escribe el otro. | G13: A
A14: ET-10 | B14: RF-04, RNF-05 | C14: Almacenamiento no volátil | D14: ≥2 | E14: GB | F14: 10 escenas crudas (1,0 GB) + comprimidas + registros ≈1,52 GB. | G14: A
A15: ET-11 | B15: RNF-04 | C15: Escritura sostenida | D15: ≥4 | E15: MB/s | F15: 6,29 MB cada 3,5 s =1,8 MB/s, con margen de 2. | G15: P
... A44: ET-40 | B44: RN-03, RN-04 | C44: Temporizadores tras despliegue | D44: 30 (antena), 45 (RF) | E44: min | F44: Implementados por hardware en el EPS, independientes del OBC. | G44: I, P

Sheet Trazabilidad
A1: Matriz de trazabilidad
A2: Copiado del informe; mantener sincronizado.
A4: Requisitos | B4: Especificaciones | C4: Elemento de arquitectura | D4: Verificación prevista (etapa)
A5: RF-01, RNF-01 a RNF-03 | B5: ET-01 a ET-04 | C5: PCB-4 (sensor), lente comercial, filtro de 4 franjas | D5: I con hojas de datos (P4); A de GSD y barrido (P4).
A6: RF-02, RF-03, RF-23, RNF-12 | B6: ET-12, ET-33, ET-34 | C6: PCB-2: MCU, RTC con TCXO; SW: planificador y SGP4 | D6: I (P4); P de deriva del reloj si hay prototipo.
A7: RF-04, RNF-04, RNF-05 | B7: ET-05 a ET-11 | C7: PCB-2: SDRAM, eMMC; interfaz IF-06 | D7: A de ancho de banda (P4); D de captura en flatsat.
A8: RF-05, RF-06, RNF-06, RNF-07 | B8: ET-19 a ET-21 | C8: PCB-3: módulo TX banda S; antena de parche; IF-08 | D8: A con datos reales del módulo elegido (P4).
A9: RF-07 a RF-09 | B9: ET-14, ET-16 a ET-18 | C9: PCB-3: transceptor UHF y MCU COM; antena UHF | D9: A (P4); D de baliza y comandos en mesa.
A10: RF-10, RF-11, RNF-13 | B10: ET-13, ET-35 | C10: Supervisor del EPS, MCU COM, watchdog externo, IF-09 | D10: A de modos de falla (P6); P de reinicios.
A11: RF-12 | B11: ET-15 | C11: PCB-2: NOR QSPI con dos ranuras y FRAM | D11: I (P4).
A12: RF-13, RNF-14 | B12: – | C12: Puerto de acceso (IF-17) y conectores de prueba | D12: I (P5).
A13: RF-14, RNF-08, RNF-09, RN-05 | B13: ET-22, ET-23 | C13: Paneles, PCB-1: MPPT y batería 2S | D13: A (P4).
A14: RF-15 a RF-18, RA-02 | B14: ET-24 a ET-27 | C14: PCB-1: LCL, monitores V/I, protección y calefactor de batería | D14: P en banco de cada protección (flatsat).
A15: RF-19 a RF-22, RNF-10, RNF-11, RNF-16 | B15: ET-28 a ET-32 | C15: PCB-2: IMU, magnetómetro, ADC de sensores de sol, puentes H; ruedas; magnetorquers | D15: A con simulación simple de orientación (P6).
... A20: RN-07, RN-08 | B20: – | C20: Vida orbital; reglas de diseño en Altium | D20: A (P6); I (P5).

Sheet Interfaces
A1: Definición preliminar de interfaces
A2: Copiado del informe; mantener sincronizado.
A4: ID | B4: Origen | C4: Destino | D4: Función | E4: Señal o protocolo | F4: Características eléctricas preliminares | G4: Tasa o volumen | H4: Observaciones
A5: IF-01 | B5: Paneles | C5: PCB-1 | D5: Energía solar | E5: DC, 5 entradas independientes | F5: 4,0–5,5 V, ≤0,5 A por cara | G5: – | H5: Diodo de bloqueo o ideal por entrada.
A6: IF-02 | B6: Paneles | C6: PCB-2 | D6: Sol y temperatura | E6: Analógico | F6: 0–3,3 V, 11 canales | G6: 10 Hz | H6: Rutear lejos de potencia; filtro RC en el OBC.
A7: IF-03 | B7: PCB-1 | C7: Todas | D7: Alimentación | E7: Rieles conmutados por LCL | F7: 3,3 V (≤1,5 A), 5 V (≤2,5 A), VBAT 6,0–8,4 V (≤2 A) | G7: – | H7: Cruza la pila; varios pines por riel.
A8: IF-04 | B8: PCB-2 | C8: PCB-1, PCB-3 | D8: TM/TC interna | E8: CAN 2.0B | F8: Diferencial, transceptores de 3,3 V, 120 Ω en extremos | G8: 500 kbit/s | H8: Cruza la pila; par trenzado equivalente en pistas.
A9: IF-05 | B9: PCB-2 | C9: PCB-1 | D9: Respaldo de TM/TC | E9: I^2C | F9: 3,3 V, pull-up en PCB-1 | G9: 100 kHz | H9: Solo si falla CAN.
A10: IF-06 | B10: PCB-4 | C10: PCB-2 | D10: Datos de imagen | E10: Paralelo 12 bit + PCLK, HSYNC, VSYNC | F10: LVCMOS 3,3 V (o 1,8 V con traductor), PCLK ≤25 MHz | G10: 6,29 MB/cuadro | H10: Cable plano ≤100 mm, longitudes igualadas, tierras intercaladas.
A11: IF-07 | B11: PCB-2 | C11: PCB-4 | D11: Configuración y disparo | E11: I^2C + GPIO | F11: 3,3 V | G11: bajo | H11: El disparo marca la estampa de tiempo.
A12: IF-08 | B12: PCB-2 | C12: PCB-3 | D12: Datos a banda S | E12: SPI | F12: LVCMOS 3,3 V, ≥4 Mbit/s | G12: 2 Mbit/s sostenidos | H12: Cruza la pila; TBD-05.
A13: IF-09 | B13: PCB-3 | C13: PCB-1 | D13: Reinicio del OBC | E13: Línea dedicada, drenador abierto | F13: 3,3 V | G13: evento | H13: Independiente del OBC.
A14: IF-10 | B14: PCB-1 | C14: PCB-2, PCB-3 | D14: Habilitación y reinicio | E14: GPIO | F14: 3,3 V | G14: evento | H14: El supervisor puede apagar y encender cada procesador.
A15: IF-11 | B15: PCB-2 | C15: Ruedas | D15: Mando y TM de ruedas | E15: UART (o según COTS) | F15: 3,3 V; alimentación 5 V por LCL | G15: 10 Hz | H15: Protocolo del fabricante.
... A22: IF-18 | B22: PCB-3 | C22: Estación | D22: Enlaces RF | E22: UHF 435–438 MHz; S 2200–2290 MHz | F22: – | G22: 9,6 kbit/s; 2 Mbit/s | H22: la tabla del informe.

Sheet TBD_Riesgos
A1: Valores por determinar (TBD)
A2: Copiado del informe; mantener sincronizado.
A4: ID | B4: Qué falta | C4: Valor supuesto | D4: Por qué sigue abierto y cómo se cierra | E4: Cierre
A5: TBD-01 | B5: Número y duración de pases sobre Medellín | C5: 1,5 pases/día de 240 s (ε≥20°) | D5: La estimación es geométrica. Se cierra simulando con GMAT o gpredict y un TLE de un satélite real en órbita parecida, incluyendo la máscara de horizonte del valle. | E5: Práctica 4
A6: TBD-02 | B6: Razón de compresión sin pérdidas | C6: 2:1 (mínimo aceptable 1,4:1) | D6: Depende de la escena. Se cierra comprimiendo recortes de Sentinel-2 con una implementación de CCSDS 123. | E6: Práctica 4
A7: TBD-03 | B7: Dosis ionizante total de la misión | C7: ≈1 krad(Si) | D7: Se cierra con SPENVIS para la órbita y el blindaje reales. | E7: Práctica 4
A8: TBD-04 | B8: Temperaturas internas y ciclo del calefactor | C8: -20 …+60°C; calefactor 20% | D8: Requiere un modelo térmico nodal sencillo. | E8: Práctica 6
A9: TBD-05 | B9: Módulo transmisor de banda S | C9: SPI ≥4 Mbit/s, ≤8 W | D9: La selección depende de disponibilidad y costo; las condiciones que debe cumplir ya están fijadas (ET-19, ET-20). | E9: Práctica 4
A10: TBD-06 | B10: Tipo de magnetorquer | C10: Varilla con núcleo, ≥0,1 Am² | D10: Varilla o bobina embebida en panel; ambas se manejan con el mismo puente H. | E10: Práctica 4
A11: TBD-07 | B11: Altura útil de la estructura | C11: 96 mm | D11: Depende del fabricante de la estructura. | E11: Práctica 5
A12: TBD-08 | B12: Clasificación regulatoria | C12: UHF aficionados, banda S investigación espacial | D12: Se cierra consultando con la IARU y la autoridad nacional. | E12: Práctica 6
A13: TBD-09 | B13: Tiempo de reingreso | C13: <25 años | D13: Se cierra con una herramienta de vida orbital (STELA o DRAMA). | E13: Práctica 6
A15: Registro de riesgos
A16: ID | B16: Riesgo | C16: Consecuencia | D16: Mitigación | E16: P | F16: I
A17: RG-01 | B17: La pila no cabe en la estructura seleccionada | C17: Rediseño de tarjetas o de la bahía | D17: Confirmar altura útil (TBD-07) antes de P5; tarjetas de perfil bajo; baterías acostadas. | E17: Media | F17: Alto
A18: RG-02 | B18: Nubosidad alta sobre la zona andina | C18: Pocas escenas útiles | D18: Tomas a media mañana (S-01), vistas previas antes de bajar, capacidad dimensionada para el máximo de oportunidades. | E18: Alta | F18: Medio
A19: RG-03 | B19: Poca señal en la banda de borde rojo (15 nm) | C19: Imágenes ruidosas en esa banda | D19: Estimar SNR en P4 con la eficiencia cuántica del sensor; si no alcanza, ensanchar la banda o agrupar píxeles. | E19: Media | F19: Medio
A20: RG-04 | B20: Latch-up en componentes comerciales | C20: Daño permanente | D20: LCL con corte en ≤1 ms y reconexión; componentes con datos de radiación cuando existan. | E20: Media | F20: Alto
A21: RG-05 | B21: Retraso en la autorización de frecuencias | C21: No se puede operar | D21: Iniciar coordinación temprano; si la misión no califica como de aficionados, migrar UHF a una banda de operación espacial. | E21: Media | F21: Alto
A22: RG-06 | B22: Menos pases útiles de los estimados | C22: Menos datos bajados | D22: Simulación en P4 (TBD-01); orientar el parche a la estación durante el pase. | E22: Media | F22: Medio
A23: RG-07 | B23: Falla del apuntamiento solar | C23: Balance de energía negativo | D23: Modo seguro con cargas mínimas; el margen de batería permite varios días. | E23: Baja | F23: Alto
A24: RG-08 | B24: Filtro de franjas a medida caro o con entrega lenta | C24: Retraso de la carga útil | D24: Cotizar en P4; alternativa D8-B como respaldo. | E24: Media | F24: Medio
A25: RG-09 | B25: Interferencia de los convertidores sobre la RF o el magnetómetro | C25: Pérdida de sensibilidad o mala actitud | D25: Frecuencias de conmutación fuera de banda, planos de tierra, separación física y apagar magnetorquers al medir. | E25: Media | F25: Medio
A26: RG-10 | B26: Batería fría durante la carga | C26: Degradación o daño | D26: Calefactor con histéresis y bloqueo de carga por temperatura en hardware. | E26: Baja | F26: Alto

Sheet Componentes
A1: Componentes candidatos por tarjeta, fabricante, referencia y hoja de datos
A2: Copiado de la Sección de componentes del informe. «Verificada» = ficha u hoja de datos consultada al armar la lista; «Por verificar» = abrir el PDF y confirmar parámetros antes de citarlo.
A4: ID | B4: Tarjeta / grupo | C4: Función | D4: Fabricante | E4: Referencia | F4: Parámetros relevantes | G4: Requisito o ET que sustenta | H4: Hoja de datos (enlace) | I4: Archivo en el repositorio (datasheets/) | J4: Estado hoja de datos | K4: Cantidad | L4: Precio unitario (USD) | M4: Subtotal (USD) | N4: Fuente del precio | O4: Observaciones
A5: E-01 | B5: PCB-1: EPS con batería | C5: Protección de batería 2S por hardware | D5: Texas Instruments | E5: BQ77307 | F5: Protector autónomo de 2 celdas en serie; corta con FET externos por sobretensión, subtensión, sobrecorriente y cortocircuito. | G5: RF-18, RN-06 | H5: https://www.ti.com/product/BQ77307 | I5: PCB1_EPS/TI_BQ77307.pdf | J5: Por verificar | K5: 1 | L5: 1.2 | M5: =K5*L5 -> 1.2 | N5: Estimado | O5: Recomendado por TI en el foro E2E para 2S; confirmar umbrales en la hoja de datos.
A6: E-02 | B6: PCB-1: EPS con batería | C6: Cargador buck-boost con MPPT | D6: Texas Instruments | E6: BQ25798 | F6: 1–4 celdas; entrada 3,6–24 V; MPPT por tensión de circuito abierto; 5 A; I2C; QFN 4×4 mm. | G6: RF-14, RF-18, ET-22, ET-23 | H6: https://www.ti.com/lit/gpn/bq25798 | I6: PCB1_EPS/TI_BQ25798.pdf | J6: Verificada | K6: 1 | L6: 3.8 | M6: =K6*L6 -> 3.8 | N6: Estimado | O6: Los cinco paneles se unen tras un diodo por entrada a un cargador; el MPPT es común (no por cara).
A7: E-03 | B7: PCB-1: EPS con batería | C7: Diodos de bloqueo (×5, uno por panel) | D7: Vishay | E7: SS34 | F7: Schottky 40 V, 3 A; unos 0,4 V de caída (≈0,2 W con 0,5 A). | G7: IF-01 | H7: https://www.vishay.com/ | I7: PCB1_EPS/Vishay_SS34.pdf | J7: Por verificar | K7: 5 | L7: 0.15 | M7: =K7*L7 -> 0.75 | N7: Estimado | O7: Alternativa con menos pérdidas: controlador de diodo ideal (p. ej. TI LM74700-Q1).
A8: E-04 | B8: PCB-1: EPS con batería | C8: Monitores de tensión y corriente (×14) | D8: Texas Instruments | E8: INA226 | F8: 16 bits, I2C, hasta 36 V, 16 direcciones; con shunt de 50 mΩ resuelve unos 50 µA. | G8: RF-16, ET-26 | H8: https://www.ti.com/lit/gpn/ina226 | I8: PCB1_EPS/TI_INA226.pdf | J8: Por verificar | K8: 14 | L8: 3.81 | M8: =K8*L8 -> 53.34 | N8: Verificado (DigiKey, sept. 2026) | O8: 14 puntos: 5 paneles, 8 líneas LCL y batería (cabe en 16 direcciones).
A9: E-05 | B9: PCB-1: EPS con batería | C9: Resistencias shunt de medición | D9: Vishay | E9: WSL2512, 50 mΩ, 1 % | F9: Baja inductancia, 2512, 1 W. | G9: RF-16, ET-26 | H9: https://www.vishay.com/ | I9: PCB1_EPS/Vishay_WSL2512.pdf | J9: Por verificar | K9: 14 | L9: 0.45 | M9: =K9*L9 -> 6.3 | N9: Estimado
A10: E-06 | B10: PCB-1: EPS con batería | C10: Regulador buck 3,3 V (≥1,5 A) | D10: Texas Instruments | E10: TPS62933 | F10: Entrada 3,8–30 V, 3 A, síncrono; cubre VBAT de 6,0 a 8,4 V. | G10: ET-24 | H10: https://www.ti.com/lit/gpn/tps62933 | I10: PCB1_EPS/TI_TPS62933.pdf | J10: Por verificar | K10: 1 | L10: 2.2 | M10: =K10*L10 -> 2.2 | N10: Estimado
A11: E-07 | B11: PCB-1: EPS con batería | C11: Regulador buck 5,0 V (≥2,5 A) | D11: Texas Instruments | E11: TPS62933 | F11: Mismo dispositivo; 3 A frente a un pico calculado de 2,24 A (margen del 34 %). | G11: ET-24 | H11: https://www.ti.com/lit/gpn/tps62933 | I11: PCB1_EPS/TI_TPS62933.pdf | J11: Por verificar | K11: 1 | L11: 2.2 | M11: =K11*L11 -> 2.2 | N11: Estimado | O11: Margen justo; si la Práctica 4 sube el pico, pasar a un regulador de 4 A.
A12: E-08 | B12: PCB-1: EPS con batería | C12: Líneas conmutadas con límite de corriente (LCL ×8) | D12: Texas Instruments | E12: TPS25947 | F12: eFuse 2,7–23 V, hasta 5,5 A, límite ajustable, disparo por cortocircuito en microsegundos. | G12: RF-15, RF-17, RA-06, ET-25 | H12: https://www.ti.com/lit/gpn/tps25947 | I12: PCB1_EPS/TI_TPS25947.pdf | J12: Por verificar | K12: 8 | L12: 2.8 | M12: =K12*L12 -> 22.4 | N12: Estimado | O12: Cumple corte ≤ 1 ms (ET-25); reconexión por línea EN.
A13: E-09 | B13: PCB-1: EPS con batería | C13: MCU supervisor de bajo consumo | D13: STMicroelectronics | E13: STM32G0B1CBT6 | F13: Cortex-M0+ 64 MHz, FDCAN, 2× I2C, ADC 12 bits, −40 a 85 °C. | G13: RF-10, RF-11, ET-35, ET-40 | H13: https://www.st.com/resource/en/datasheet/stm32g0b1cb.pdf | I13: PCB1_EPS/ST_STM32G0B1.pdf | J13: Por verificar | K13: 1 | L13: 3.6 | M13: =K13*L13 -> 3.6 | N13: Estimado | O13: El mismo MCU se usa en COM (una sola cadena de herramientas).
A14: E-10 | B14: PCB-1: EPS con batería | C14: Transceptor CAN de 3,3 V | D14: Texas Instruments | E14: SN65HVD230 | F14: CAN a 3,3 V, hasta 1 Mbit/s, −40 a 85 °C. | G14: IF-04, ET-13 | H14: https://www.ti.com/lit/gpn/sn65hvd230 | I14: COMUN/TI_SN65HVD230.pdf | J14: Por verificar | K14: 1 | L14: 1.55 | M14: =K14*L14 -> 1.55 | N14: Estimado | O14: Se repite en PCB-2 y PCB-3; terminación de 120 Ω en los extremos.
A15: E-11 | B15: PCB-1: EPS con batería | C15: Temporizadores por hardware (×2: 30 min y 45 min) | D15: Texas Instruments | E15: TPL5110 | F15: Temporizador de nanopotencia, retardo de 100 ms a 7200 s con resistencia externa. | G15: RN-04, ET-40 | H15: https://www.ti.com/lit/gpn/tpl5110 | I15: PCB1_EPS/TI_TPL5110.pdf | J15: Por verificar | K15: 2 | L15: 1.1 | M15: =K15*L15 -> 2.2 | N15: Estimado | O15: 7200 s cubre 30 min (1800 s) y 45 min (2700 s).
A16: E-12 | B16: PCB-1: EPS con batería | C16: MOSFET de potencia (calefactor, hilo térmico, FET de protección) | D16: Infineon | E16: IRLML6344TRPbF | F16: N-canal 30 V, ≈5 A, compuerta a nivel lógico, SOT-23. | G16: RF-18, IF-15 | H16: https://www.infineon.com/ | I16: PCB1_EPS/Infineon_IRLML6344.pdf | J16: Por verificar | K16: 3 | L16: 0.55 | M16: =K16*L16 -> 1.65 | N16: Estimado | O16: Verificar RDS(on) a la tensión de compuerta real (3,3 V).
A17: E-13 | B17: PCB-1: EPS con batería | C17: Calefactor de batería (0,5 W) | D17: Vishay | E17: CRCW2512120RFKEG | F17: 120 Ω, 1 %, 2512, 1 W: 0,46 W a 7,4 V y 0,59 W a 8,4 V. | G17: RA-02, ET-27 | H17: https://www.vishay.com/ | I17: PCB1_EPS/Vishay_CRCW2512.pdf | J17: Por verificar | K17: 1 | L17: 0.2 | M17: =K17*L17 -> 0.2 | N17: Estimado
A18: E-14 | B18: PCB-1: EPS con batería | C18: Sensores de temperatura NTC (batería, paneles, PA) | D18: Murata | E18: NCP15XH103F03RC | F18: NTC 10 kΩ, 0402, −40 a 125 °C. | G18: RA-02, RF-16 | H18: https://www.murata.com/ | I18: COMUN/Murata_NCP15XH103F03RC.pdf | J18: Por verificar | K18: 8 | L18: 0.3 | M18: =K18*L18 -> 2.4 | N18: Estimado
A19: E-15 | B19: PCB-1: EPS con batería | C19: Interruptores de despliegue (señal de inhibición) | D19: Omron | E19: D2F-01F | F19: Microinterruptor subminiatura; solo maneja la señal lógica, la corriente la conmuta un MOSFET. | G19: RN-03, IF-16 | H19: https://components.omron.com/ | I19: PCB1_EPS/Omron_D2F.pdf | J19: Por verificar | K19: 2 | L19: 1.1 | M19: =K19*L19 -> 2.2 | N19: Estimado | O19: El pin RBF es un elemento mecánico del rail; definir en la Práctica 4.
A20: E-16 | B20: PCB-1: EPS con batería | C20: Conector de pila (2×26, tipo PC/104) | D20: Samtec | E20: ESQ-126-39-G-D | F20: Zócalo apilable 2×26, paso 2,54 mm. | G20: IF-03, IF-04 | H20: https://www.samtec.com/products/esq | I20: COMUN/Samtec_ESQ.pdf | J20: Por verificar | K20: 1 | L20: 3.2 | M20: =K20*L20 -> 3.2 | N20: Estimado | O20: Mismo conector en las cuatro tarjetas; pines de potencia en paralelo.
A21: O-01 | B21: PCB-2: OBC y orientación | C21: Microcontrolador central | D21: STMicroelectronics | E21: STM32H743IIT6 | F21: Cortex-M7 a 480 MHz, 2 MB de flash, 1 MB de RAM con ECC, DCMI, FMC, SDMMC, QSPI, FDCAN; −40 a 85 °C. | G21: ET-12, ET-36, RA-06 | H21: https://www.st.com/resource/en/datasheet/stm32h743ii.pdf | I21: PCB2_OBC/ST_STM32H743.pdf | J21: Por verificar | K21: 1 | L21: 16.84 | M21: =K21*L21 -> 16.84 | N21: Verificado (DigiKey, sept. 2026) | O21: Es el candidato de la referencia [16]; el encapsulado LQFP176 da los pines que pide la Sección V-B.
A22: O-02 | B22: PCB-2: OBC y orientación | C22: SDRAM de 32 MB | D22: ISSI | E22: IS42S16160J-6TLI | F22: 256 Mbit (16 M×16), 3,3 V, 166 MHz, grado industrial. | G22: ET-09 | H22: https://www.issi.com/WW/pdf/42-45S16160J.pdf | I22: PCB2_OBC/ISSI_IS42S16160J.pdf | J22: Por verificar | K22: 1 | L22: 3.4 | M22: =K22*L22 -> 3.4 | N22: Estimado | O22: Dos cuadros de 5,97 MB caben con margen (ver hallazgo del sensor).
A23: O-03 | B23: PCB-2: OBC y orientación | C23: Almacenamiento masivo eMMC de 4 GB | D23: Micron | E23: MTFC4GACAJCN-4M IT | F23: 4 GB, eMMC 5.0, 153 bolas, 2,7–3,6 V, −40 a 85 °C. | G23: ET-10, ET-11, ET-38 | H23: https://www.micron.com/ | I23: PCB2_OBC/Micron_MTFC4GACAJCN.pdf | J23: Verificada | K23: 1 | L23: 9.5 | M23: =K23*L23 -> 9.5 | N23: Estimado (fin de vida; ver H-08) | O23: Micron la marca como fin de vida: riesgo para RNF-17; buscar un eMMC industrial equivalente vigente.
A24: O-04 | B24: PCB-2: OBC y orientación | C24: Flash NOR QSPI (2 ranuras de software + respaldo) | D24: Winbond | E24: W25Q128JVSIQ | F24: 128 Mbit (16 MB), QSPI, −40 a 85 °C. | G24: ET-15, RF-12 | H24: https://www.winbond.com/ | I24: PCB2_OBC/Winbond_W25Q128JV.pdf | J24: Por verificar | K24: 1 | L24: 2.1 | M24: =K24*L24 -> 2.1 | N24: Estimado
A25: O-05 | B25: PCB-2: OBC y orientación | C25: FRAM para contadores y parámetros críticos | D25: Infineon | E25: FM25V10-G | F25: 1 Mbit, SPI a 40 MHz, escrituras prácticamente ilimitadas. | G25: ET-36 | H25: https://www.infineon.com/ | I25: PCB2_OBC/Infineon_FM25V10.pdf | J25: Por verificar | K25: 1 | L25: 4.6 | M25: =K25*L25 -> 4.6 | N25: Estimado
A26: O-06 | B26: PCB-2: OBC y orientación | C26: RTC con TCXO | D26: Analog Devices (Maxim) | E26: DS3231SN | F26: TCXO integrado, ±3,5 ppm de −40 a 85 °C, I2C. | G26: RNF-12, ET-34 | H26: https://www.analog.com/en/products/ds3231.html | I26: PCB2_OBC/ADI_DS3231.pdf | J26: Por verificar | K26: 1 | L26: 6.5 | M26: =K26*L26 -> 6.5 | N26: Estimado | O26: 3,5 ppm ≈ 0,30 s/día (ET-34 pide ≤ 5 ppm).
A27: O-07 | B27: PCB-2: OBC y orientación | C27: Watchdog externo (2 s) | D27: Texas Instruments | E27: TPS3431 | F27: Watchdog con tiempo programable y salida de reinicio. | G27: RF-11, ET-35 | H27: https://www.ti.com/lit/gpn/tps3431 | I27: PCB2_OBC/TI_TPS3431.pdf | J27: Por verificar | K27: 1 | L27: 1.3 | M27: =K27*L27 -> 1.3 | N27: Estimado
A28: O-08 | B28: PCB-2: OBC y orientación | C28: IMU (giroscopio y acelerómetro) | D28: Bosch Sensortec | E28: BMI088 | F28: Giroscopio ±2000 °/s y acelerómetro de 3 ejes, SPI/I2C, −40 a 85 °C. | G28: RF-19, ET-28 | H28: https://www.bosch-sensortec.com/products/motion-sensors/imus/bmi088/ | I28: PCB2_OBC/Bosch_BMI088.pdf | J28: Por verificar | K28: 1 | L28: 8.9 | M28: =K28*L28 -> 8.9 | N28: Estimado
A29: O-09 | B29: PCB-2: OBC y orientación | C29: Magnetómetro de 3 ejes | D29: PNI Sensor Corporation | E29: RM3100 | F29: Sensor geomagnético de bajo ruido, SPI/I2C, rango del orden de ±800 µT. | G29: RF-19, ET-28, RNF-16 | H29: https://www.pnicorp.com/rm3100/ | I29: PCB2_OBC/PNI_RM3100.pdf | J29: Por verificar | K29: 1 | L29: 28 | M29: =K29*L29 -> 28 | N29: Estimado | O29: Ubicar lejos de los puentes H y de las pistas de alta corriente.
A30: O-10 | B30: PCB-2: OBC y orientación | C30: Drivers de puente H para magnetorquers (×3) | D30: Texas Instruments | E30: DRV8837 | F30: Puente H de 1,8 A, 1,8–11 V; se alimenta con los 5 V del EPS. | G30: RF-20, RF-22, IF-12 | H30: https://www.ti.com/lit/gpn/drv8837 | I30: PCB2_OBC/TI_DRV8837.pdf | J30: Por verificar | K30: 3 | L30: 0.85 | M30: =K30*L30 -> 2.55 | N30: Estimado | O30: Se apagan mientras se lee el magnetómetro.
A31: O-11 | B31: PCB-2: OBC y orientación | C31: Transceptor CAN de 3,3 V | D31: Texas Instruments | E31: SN65HVD230 | F31: Igual que E-10. | G31: IF-04 | H31: https://www.ti.com/lit/gpn/sn65hvd230 | I31: COMUN/TI_SN65HVD230.pdf | J31: Por verificar | K31: 1 | L31: 1.55 | M31: =K31*L31 -> 1.55 | N31: Estimado
A32: O-12 | B32: PCB-2: OBC y orientación | C32: Conector plano de cámara (FFC, 30 vías) | D32: Hirose | E32: FH12-30S-0.5SH(55) | F32: FFC de 0,5 mm, 30 vías; alcanza 12 bits + PCLK, HSYNC, VSYNC, I2C, disparo y alimentación. | G32: IF-06, IF-07 | H32: https://www.hirose.com/ | I32: PCB2_OBC/Hirose_FH12.pdf | J32: Por verificar | K32: 1 | L32: 1.1 | M32: =K32*L32 -> 1.1 | N32: Estimado | O32: Contar las señales de IF-06 e IF-07 antes de fijar las 30 vías.
A33: O-13 | B33: PCB-2: OBC y orientación | C33: Conector de depuración SWD | D33: Samtec | E33: FTSH-105-01-L-DV-K | F33: Cabezal de 10 pines, paso 1,27 mm (Cortex Debug). | G33: RF-13, RNF-14 | H33: https://www.samtec.com/products/ftsh | I33: COMUN/Samtec_FTSH.pdf | J33: Por verificar | K33: 1 | L33: 0.95 | M33: =K33*L33 -> 0.95 | N33: Estimado
A34: O-14 | B34: PCB-2: OBC y orientación | C34: Conector de pila | D34: Samtec | E34: ESQ-126-39-G-D | F34: Igual que E-16. | G34: IF-03, IF-04 | H34: https://www.samtec.com/products/esq | I34: COMUN/Samtec_ESQ.pdf | J34: Por verificar | K34: 1 | L34: 3.2 | M34: =K34*L34 -> 3.2 | N34: Estimado
A35: C-01 | B35: PCB-3: comunicaciones | C35: MCU de comunicaciones | D35: STMicroelectronics | E35: STM32G0B1CBT6 | F35: Igual que E-09; SPI para la banda S y el UHF, FDCAN y UART. | G35: RF-11, RF-07, IF-08, IF-09 | H35: https://www.st.com/resource/en/datasheet/stm32g0b1cb.pdf | I35: PCB1_EPS/ST_STM32G0B1.pdf | J35: Por verificar | K35: 1 | L35: 3.6 | M35: =K35*L35 -> 3.6 | N35: Estimado
A36: C-02 | B36: PCB-3: comunicaciones | C36: Transceptor UHF (435–438 MHz) | D36: Silicon Labs | E36: Si4463-C2A-GM | F36: 142–1050 MHz, (G)FSK/GMSK hasta 1 Mbit/s, +20 dBm, sensibilidad −129 dBm, 1,8–3,8 V. | G36: RF-07, RF-08, ET-16, ET-18 | H36: https://www.silabs.com/documents/public/data-sheets/Si4464-63-61-60.pdf | I36: PCB3_COM/SiLabs_Si4463.pdf | J36: Verificada | K36: 1 | L36: 3.2 | M36: =K36*L36 -> 3.2 | N36: Estimado | O36: La sensibilidad supera con mucho los −110 dBm de ET-18; el LNA externo queda opcional.
A37: C-03 | B37: PCB-3: comunicaciones | C37: Amplificador de potencia UHF (1 W) | D37: Guerrilla RF | E37: GRF5504 | F37: 400–500 MHz, 5 V, hasta 35,5 dBm de saturación, ≈64 % de eficiencia, ganancia 41 dB, −40 a 85 °C. | G37: ET-17 | H37: https://www.mouser.in/new/guerrilla-rf/guerrilla-rf-grf5504-power-amplifier | I37: PCB3_COM/GuerrillaRF_GRF5504.pdf | J37: Verificada | K37: 1 | L37: 4.5 | M37: =K37*L37 -> 4.5 | N37: Estimado | O37: Hay que atenuar la excitación de +20 dBm del Si4463; la eficiencia real dependerá de la red de adaptación.
A38: C-04 | B38: PCB-3: comunicaciones | C38: Interruptor de RF transmisión/recepción | D38: pSemi (Murata) | E38: PE4259 | F38: SPDT de banda ancha (hasta unos 3 GHz), control lógico. | G38: ET-16 | H38: https://www.psemi.com/ | I38: PCB3_COM/pSemi_PE4259.pdf | J38: Por verificar | K38: 1 | L38: 2.5 | M38: =K38*L38 -> 2.5 | N38: Estimado | O38: Confirmar la potencia máxima admitida (>30 dBm) antes de fijarlo.
A39: C-05 | B39: PCB-3: comunicaciones | C39: Filtro pasa-bajos de armónicos UHF | D39: Mini-Circuits | E39: LFCN-490+ | F39: Pasa-bajos cerámico LTCC, DC–490 MHz. | G39: RN-06, ET-17 | H39: https://www.minicircuits.com/ | I39: PCB3_COM/MiniCircuits_LFCN-490.pdf | J39: Por verificar | K39: 1 | L39: 9.95 | M39: =K39*L39 -> 9.95 | N39: Estimado | O39: Comprobar la pérdida de inserción a 437 MHz y la potencia admitida.
A40: C-06 | B40: PCB-3: comunicaciones | C40: Módulo transmisor de banda S (COTS) | D40: AAC Clyde Space | E40: PULSAR-STXC | F40: 2,2–2,3 GHz, QPSK/OQPSK hasta 2 Mbit/s, 24–30 dBm, < 5 W, 6–12 V, SPI a 4 MHz (datos) e I2C a 400 kHz. | G40: RF-05, ET-19, ET-20, TBD-05 | H40: https://www.aac-clyde.space/wp-content/uploads/2021/10/Pulsar-STX-S-band.pdf | I40: PCB3_COM/AAC_Pulsar-STX.pdf | J40: Verificada | K40: 1 | L40: Por cotizar | M40: — | N40: Por cotizar (COTS espacial; orden de magnitud típico USD 8 000-15 000) | O40: Mide 96×90×16,9 mm y es una tarjeta completa; ver hallazgos de volumen y temperatura.
A41: C-07 | B41: PCB-3: comunicaciones | C41: Transceptor CAN de 3,3 V | D41: Texas Instruments | E41: SN65HVD230 | F41: Igual que E-10. | G41: IF-04 | H41: https://www.ti.com/lit/gpn/sn65hvd230 | I41: COMUN/TI_SN65HVD230.pdf | J41: Por verificar | K41: 1 | L41: 1.55 | M41: =K41*L41 -> 1.55 | N41: Estimado
...

Sheet Hallazgos_Componentes
A1: Hallazgos al contrastar los componentes con especificaciones y presupuestos
A2: Cada fila cambia o pone en riesgo un número ya reportado; resolver antes de la Práctica 5 y reflejar en RG-01 y en las Tablas XVIII y XVII.
A4: ID | B4: Componente | C4: Hallazgo | D4: Impacto | E4: Acción propuesta | F4: Afecta a
